File: diff_X/ray_tracing/calib/2019_theta_2theta_LaB6_detecteurFente025.csv
[Measurement conditions]
Sample identification,
Comment - 1,"Configuration=2018HybrideTripleAxis, Owner=User-1, Creation date=19/10/2018 14:17:25"
Comment - 2,"Goniometer=PW3050/20 HR  (Theta/2Theta); Minimum step size 2Theta:0.001; Minimum step size Omega:0.001"
Comment - 3,"Sample stage=MRD Cradle; Minimum step size Phi:0.01; Minimum step size Psi:0.01; Minimum step size X:0.01; Minimum step size Y:0.01; Minimum step size Z:0.001"
Comment - 4,"Diffractometer system=XPERT-MPD"
Comment - 5,"Measurement program=2019_THETA-2THETA LaB6poudre, Owner=stephanie, Creation date=29/04/2019 15:33:27"
Comment - 6,"Fine Calibration Offset for 2Theta = 2.919 deg"
Comment - 7,"Fine Calibration Offset for Omega = 2.880 deg"
Comment - 8,"Batch program=2019_05_03_batch_mesureMylarVerre, Owner=stephanie, Creation date=03/05/2019 15:56:22"
Anode material,Cu
K-Alpha1 wavelength,1.5405980
K-Alpha2 wavelength,1.5444260
Ratio K-Alpha2/K-Alpha1,0.000
Monochromator used,YES
Generator voltage, 40
Tube current, 30
File date and time,03/mai/2019 16:15
Unit cell,
h k l, 0 0 0
Scan axis,2Theta-Omega
Scan range,18.0000,90.0000
Scan step size,0.0100000
Omega offset,-0.0890
No. of points, 7200
Scan type,CONTINUOUS
Phi,0.00
Psi,0.00
X,10.00
Y,35.00
Z,7.827
Time per step,15.00
[Scan points]
Angle,Intensity
18.0050,227.0
18.0550,201.0
18.1050,208.0
18.1550,207.0
18.2050,219.0
18.2550,208.0
18.3050,215.0
18.3550,214.0
18.4050,202.0
18.4550,193.0
18.5050,250.0
18.5550,200.0
18.6050,197.0
18.6550,225.0
18.7050,221.0
18.7550,226.0
18.8050,203.0
18.8550,219.0
18.9050,197.0
18.9550,223.0
19.0050,215.0
19.0550,219.0
19.1050,210.0
19.1550,204.0
19.2050,216.0
19.2550,237.0
19.3050,215.0
19.3550,205.0
19.4050,230.0
19.4550,193.0
19.5050,216.0
19.5550,199.0
19.6050,201.0
19.6550,185.0
19.7050,207.0
19.7550,213.0
19.8050,208.0
19.8550,243.0
19.9050,231.0
19.9550,218.0
20.0050,200.0
20.0550,210.0
20.1050,237.0
20.1550,234.0
20.2050,172.0
20.2550,235.0
20.3050,217.0
20.3550,202.0
20.4050,226.0
20.4550,232.0
20.5050,222.0
20.5550,217.0
20.6050,226.0
20.6550,249.0
20.7050,242.0
20.7550,261.0
20.8050,258.0
20.8550,269.0
20.9050,336.0
20.9550,346.0
21.0050,356.0
21.0550,370.0
21.1050,428.0
21.1550,566.0
21.2050,849.0
21.2550,1092.0
21.3050,1130.0
21.3550,704.0
21.4050,302.0
21.4550,243.0
21.5050,260.0
21.5550,222.0
21.6050,274.0
21.6550,255.0
21.7050,207.0
21.7550,247.0
21.8050,245.0
21.8550,228.0
21.9050,219.0
21.9550,285.0
22.0050,260.0
22.0550,249.0
22.1050,263.0
22.1550,264.0
22.2050,274.0
22.2550,276.0
22.3050,264.0
22.3550,287.0
22.4050,293.0
22.4550,252.0
22.5050,285.0
22.5550,262.0
22.6050,318.0
22.6550,283.0
22.7050,323.0
22.7550,289.0
22.8050,317.0
22.8550,296.0
22.9050,308.0
22.9550,288.0
23.0050,290.0
23.0550,309.0
23.1050,306.0
23.1550,316.0
23.2050,286.0
23.2550,274.0
23.3050,328.0
23.3550,319.0
23.4050,299.0
23.4550,260.0
23.5050,259.0
23.5550,316.0
23.6050,314.0
23.6550,315.0
23.7050,278.0
23.7550,302.0
23.8050,338.0
23.8550,324.0
23.9050,286.0
23.9550,331.0
24.0050,338.0
24.0550,349.0
24.1050,339.0
24.1550,370.0
24.2050,333.0
24.2550,382.0
24.3050,367.0
24.3550,376.0
24.4050,398.0
24.4550,408.0
24.5050,421.0
24.5550,430.0
24.6050,421.0
24.6550,469.0
24.7050,447.0
24.7550,458.0
24.8050,491.0
24.8550,525.0
24.9050,545.0
24.9550,538.0
25.0050,648.0
25.0550,653.0
25.1050,653.0
25.1550,675.0
25.2050,684.0
25.2550,813.0
25.3050,750.0
25.3550,869.0
25.4050,893.0
25.4550,903.0
25.5050,950.0
25.5550,1021.0
25.6050,958.0
25.6550,1018.0
25.7050,998.0
25.7550,1103.0
25.8050,1072.0
25.8550,1068.0
25.9050,1096.0
25.9550,1040.0
26.0050,1036.0
26.0550,997.0
26.1050,986.0
26.1550,939.0
26.2050,917.0
26.2550,841.0
26.3050,834.0
26.3550,793.0
26.4050,721.0
26.4550,718.0
26.5050,687.0
26.5550,608.0
26.6050,594.0
26.6550,562.0
26.7050,501.0
26.7550,552.0
26.8050,505.0
26.8550,462.0
26.9050,461.0
26.9550,408.0
27.0050,381.0
27.0550,406.0
27.1050,363.0
27.1550,375.0
27.2050,333.0
27.2550,310.0
27.3050,278.0
27.3550,323.0
27.4050,269.0
27.4550,258.0
27.5050,256.0
27.5550,246.0
27.6050,234.0
27.6550,239.0
27.7050,246.0
27.7550,227.0
27.8050,215.0
27.8550,220.0
27.9050,230.0
27.9550,191.0
28.0050,188.0
28.0550,194.0
28.1050,205.0
28.1550,201.0
28.2050,200.0
28.2550,198.0
28.3050,187.0
28.3550,202.0
28.4050,192.0
28.4550,161.0
28.5050,173.0
28.5550,158.0
28.6050,141.0
28.6550,146.0
28.7050,168.0
28.7550,168.0
28.8050,183.0
28.8550,151.0
28.9050,134.0
28.9550,131.0
29.0050,143.0
29.0550,140.0
29.1050,180.0
29.1550,126.0
29.2050,140.0
29.2550,153.0
29.3050,128.0
29.3550,160.0
29.4050,146.0
29.4550,178.0
29.5050,128.0
29.5550,151.0
29.6050,150.0
29.6550,144.0
29.7050,148.0
29.7550,152.0
29.8050,152.0
29.8550,168.0
29.9050,203.0
29.9550,236.0
30.0050,326.0
30.0550,396.0
30.1050,469.0
30.1550,707.0
30.2050,1117.0
30.2550,1593.0
30.3050,2081.0
30.3550,1577.0
30.4050,397.0
30.4550,182.0
30.5050,149.0
30.5550,162.0
30.6050,131.0
30.6550,162.0
30.7050,127.0
30.7550,122.0
30.8050,136.0
30.8550,115.0
30.9050,129.0
30.9550,111.0
31.0050,127.0
31.0550,135.0
31.1050,120.0
31.1550,122.0
31.2050,142.0
31.2550,114.0
31.3050,115.0
31.3550,105.0
31.4050,127.0
31.4550,139.0
31.5050,114.0
31.5550,115.0
31.6050,123.0
31.6550,115.0
31.7050,125.0
31.7550,113.0
31.8050,114.0
31.8550,131.0
31.9050,107.0
31.9550,107.0
32.0050,96.0
32.0550,133.0
32.1050,120.0
32.1550,105.0
32.2050,119.0
32.2550,116.0
32.3050,113.0
32.3550,105.0
32.4050,115.0
32.4550,113.0
32.5050,107.0
32.5550,123.0
32.6050,97.0
32.6550,114.0
32.7050,104.0
32.7550,98.0
32.8050,102.0
32.8550,110.0
32.9050,123.0
32.9550,116.0
33.0050,113.0
33.0550,94.0
33.1050,105.0
33.1550,97.0
33.2050,95.0
33.2550,99.0
33.3050,109.0
33.3550,98.0
33.4050,82.0
33.4550,95.0
33.5050,87.0
33.5550,111.0
33.6050,104.0
33.6550,99.0
33.7050,94.0
33.7550,103.0
33.8050,107.0
33.8550,83.0
33.9050,92.0
33.9550,119.0
34.0050,85.0
34.0550,97.0
34.1050,91.0
34.1550,100.0
34.2050,108.0
34.2550,80.0
34.3050,86.0
34.3550,114.0
34.4050,95.0
34.4550,106.0
34.5050,100.0
34.5550,101.0
34.6050,99.0
34.6550,96.0
34.7050,77.0
34.7550,93.0
34.8050,107.0
34.8550,87.0
34.9050,104.0
34.9550,81.0
35.0050,102.0
35.0550,100.0
35.1050,87.0
35.1550,98.0
35.2050,80.0
35.2550,81.0
35.3050,83.0
35.3550,71.0
35.4050,89.0
35.4550,93.0
35.5050,103.0
35.5550,92.0
35.6050,89.0
35.6550,86.0
35.7050,93.0
35.7550,93.0
35.8050,79.0
35.8550,71.0
35.9050,104.0
35.9550,81.0
36.0050,100.0
36.0550,98.0
36.1050,104.0
36.1550,111.0
36.2050,76.0
36.2550,85.0
36.3050,101.0
36.3550,84.0
36.4050,85.0
36.4550,97.0
36.5050,81.0
36.5550,96.0
36.6050,88.0
36.6550,84.0
36.7050,92.0
36.7550,82.0
36.8050,106.0
36.8550,101.0
36.9050,90.0
36.9550,111.0
37.0050,107.0
37.0550,125.0
37.1050,168.0
37.1550,240.0
37.2050,419.0
37.2550,477.0
37.3050,724.0
37.3550,1002.0
37.4050,641.0
37.4550,207.0
37.5050,121.0
37.5550,94.0
37.6050,96.0
37.6550,100.0
37.7050,95.0
37.7550,93.0
37.8050,70.0
37.8550,82.0
37.9050,66.0
37.9550,88.0
38.0050,73.0
38.0550,90.0
38.1050,93.0
38.1550,90.0
38.2050,82.0
38.2550,88.0
38.3050,73.0
38.3550,89.0
38.4050,92.0
38.4550,77.0
38.5050,74.0
38.5550,94.0
38.6050,106.0
38.6550,83.0
38.7050,82.0
38.7550,81.0
38.8050,65.0
38.8550,69.0
38.9050,86.0
38.9550,68.0
39.0050,79.0
39.0550,77.0
39.1050,87.0
39.1550,90.0
39.2050,82.0
39.2550,90.0
39.3050,91.0
39.3550,89.0
39.4050,72.0
39.4550,67.0
39.5050,81.0
39.5550,75.0
39.6050,68.0
39.6550,69.0
39.7050,77.0
39.7550,73.0
39.8050,77.0
39.8550,66.0
39.9050,89.0
39.9550,69.0
40.0050,72.0
40.0550,87.0
40.1050,94.0
40.1550,74.0
40.2050,88.0
40.2550,81.0
40.3050,84.0
40.3550,74.0
40.4050,82.0
40.4550,69.0
40.5050,84.0
40.5550,88.0
40.6050,66.0
40.6550,82.0
40.7050,72.0
40.7550,85.0
40.8050,88.0
40.8550,69.0
40.9050,76.0
40.9550,70.0
41.0050,76.0
41.0550,67.0
41.1050,81.0
41.1550,71.0
41.2050,85.0
41.2550,66.0
41.3050,77.0
41.3550,85.0
41.4050,66.0
41.4550,56.0
41.5050,58.0
41.5550,70.0
41.6050,66.0
41.6550,70.0
41.7050,70.0
41.7550,61.0
41.8050,84.0
41.8550,71.0
41.9050,78.0
41.9550,90.0
42.0050,69.0
42.0550,63.0
42.1050,75.0
42.1550,86.0
42.2050,84.0
42.2550,87.0
42.3050,71.0
42.3550,68.0
42.4050,69.0
42.4550,73.0
42.5050,80.0
42.5550,74.0
42.6050,67.0
42.6550,64.0
42.7050,91.0
42.7550,71.0
42.8050,66.0
42.8550,69.0
42.9050,59.0
42.9550,81.0
43.0050,68.0
43.0550,71.0
43.1050,77.0
43.1550,101.0
43.2050,121.0
43.2550,145.0
43.3050,250.0
43.3550,380.0
43.4050,655.0
43.4550,442.0
43.5050,209.0
43.5550,92.0
43.6050,76.0
43.6550,81.0
43.7050,76.0
43.7550,78.0
43.8050,71.0
43.8550,67.0
43.9050,67.0
43.9550,89.0
44.0050,80.0
44.0550,51.0
44.1050,63.0
44.1550,67.0
44.2050,68.0
44.2550,59.0
44.3050,61.0
44.3550,85.0
44.4050,63.0
44.4550,65.0
44.5050,65.0
44.5550,67.0
44.6050,67.0
44.6550,82.0
44.7050,62.0
44.7550,79.0
44.8050,60.0
44.8550,72.0
44.9050,60.0
44.9550,76.0
45.0050,62.0
45.0550,77.0
45.1050,65.0
45.1550,71.0
45.2050,66.0
45.2550,75.0
45.3050,72.0
45.3550,75.0
45.4050,66.0
45.4550,61.0
45.5050,71.0
45.5550,71.0
45.6050,54.0
45.6550,55.0
45.7050,59.0
45.7550,62.0
45.8050,87.0
45.8550,57.0
45.9050,74.0
45.9550,56.0
46.0050,63.0
46.0550,68.0
46.1050,61.0
46.1550,73.0
46.2050,58.0
46.2550,74.0
46.3050,67.0
46.3550,72.0
46.4050,63.0
46.4550,81.0
46.5050,63.0
46.5550,56.0
46.6050,68.0
46.6550,72.0
46.7050,66.0
46.7550,72.0
46.8050,78.0
46.8550,57.0
46.9050,76.0
46.9550,77.0
47.0050,55.0
47.0550,73.0
47.1050,84.0
47.1550,48.0
47.2050,68.0
47.2550,68.0
47.3050,69.0
47.3550,53.0
47.4050,64.0
47.4550,66.0
47.5050,65.0
47.5550,61.0
47.6050,72.0
47.6550,59.0
47.7050,70.0
47.7550,76.0
47.8050,65.0
47.8550,55.0
47.9050,52.0
47.9550,86.0
48.0050,69.0
48.0550,62.0
48.1050,72.0
48.1550,83.0
48.2050,65.0
48.2550,75.0
48.3050,53.0
48.3550,65.0
48.4050,69.0
48.4550,74.0
48.5050,83.0
48.5550,88.0
48.6050,126.0
48.6550,200.0
48.7050,371.0
48.7550,445.0
48.8050,756.0
48.8550,1052.0
48.9050,1069.0
48.9550,369.0
49.0050,107.0
49.0550,77.0
49.1050,78.0
49.1550,78.0
49.2050,79.0
49.2550,69.0
49.3050,71.0
49.3550,66.0
49.4050,61.0
49.4550,67.0
49.5050,54.0
49.5550,61.0
49.6050,74.0
49.6550,66.0
49.7050,59.0
49.7550,53.0
49.8050,60.0
49.8550,39.0
49.9050,53.0
49.9550,56.0
50.0050,44.0
50.0550,60.0
50.1050,44.0
50.1550,57.0
50.2050,55.0
50.2550,60.0
50.3050,44.0
50.3550,56.0
50.4050,62.0
50.4550,54.0
50.5050,38.0
50.5550,54.0
50.6050,40.0
50.6550,46.0
50.7050,61.0
50.7550,71.0
50.8050,55.0
50.8550,60.0
50.9050,53.0
50.9550,47.0
51.0050,56.0
51.0550,58.0
51.1050,56.0
51.1550,50.0
51.2050,57.0
51.2550,63.0
51.3050,59.0
51.3550,50.0
51.4050,57.0
51.4550,69.0
51.5050,59.0
51.5550,42.0
51.6050,54.0
51.6550,64.0
51.7050,66.0
51.7550,50.0
51.8050,53.0
51.8550,46.0
51.9050,48.0
51.9550,53.0
52.0050,57.0
52.0550,56.0
52.1050,64.0
52.1550,60.0
52.2050,49.0
52.2550,46.0
52.3050,62.0
52.3550,54.0
52.4050,50.0
52.4550,61.0
52.5050,58.0
52.5550,51.0
52.6050,50.0
52.6550,55.0
52.7050,50.0
52.7550,54.0
52.8050,57.0
52.8550,66.0
52.9050,44.0
52.9550,58.0
53.0050,66.0
53.0550,66.0
53.1050,51.0
53.1550,46.0
53.2050,52.0
53.2550,49.0
53.3050,65.0
53.3550,63.0
53.4050,71.0
53.4550,61.0
53.5050,65.0
53.5550,74.0
53.6050,70.0
53.6550,105.0
53.7050,150.0
53.7550,205.0
53.8050,324.0
53.8550,569.0
53.9050,578.0
53.9550,451.0
54.0050,179.0
54.0550,96.0
54.1050,61.0
54.1550,60.0
54.2050,50.0
54.2550,54.0
54.3050,62.0
54.3550,55.0
54.4050,65.0
54.4550,46.0
54.5050,51.0
54.5550,57.0
54.6050,65.0
54.6550,57.0
54.7050,50.0
54.7550,55.0
54.8050,48.0
54.8550,61.0
54.9050,56.0
54.9550,42.0
55.0050,44.0
55.0550,46.0
55.1050,46.0
55.1550,41.0
55.2050,60.0
55.2550,44.0
55.3050,43.0
55.3550,49.0
55.4050,41.0
55.4550,46.0
55.5050,45.0
55.5550,46.0
55.6050,36.0
55.6550,43.0
55.7050,43.0
55.7550,42.0
55.8050,41.0
55.8550,41.0
55.9050,43.0
55.9550,38.0
56.0050,55.0
56.0550,34.0
56.1050,44.0
56.1550,50.0
56.2050,37.0
56.2550,55.0
56.3050,38.0
56.3550,49.0
56.4050,42.0
56.4550,38.0
56.5050,35.0
56.5550,45.0
56.6050,37.0
56.6550,40.0
56.7050,51.0
56.7550,53.0
56.8050,46.0
56.8550,41.0
56.9050,35.0
56.9550,35.0
57.0050,36.0
57.0550,30.0
57.1050,33.0
57.1550,38.0
57.2050,46.0
57.2550,53.0
57.3050,48.0
57.3550,46.0
57.4050,38.0
57.4550,44.0
57.5050,49.0
57.5550,41.0
57.6050,42.0
57.6550,44.0
57.7050,50.0
57.7550,36.0
57.8050,33.0
57.8550,35.0
57.9050,38.0
57.9550,42.0
58.0050,41.0
58.0550,43.0
58.1050,33.0
58.1550,44.0
58.2050,34.0
58.2550,36.0
58.3050,46.0
58.3550,38.0
58.4050,34.0
58.4550,39.0
58.5050,40.0
58.5550,43.0
58.6050,33.0
58.6550,36.0
58.7050,40.0
58.7550,41.0
58.8050,50.0
58.8550,39.0
58.9050,35.0
58.9550,36.0
59.0050,39.0
59.0550,32.0
59.1050,38.0
59.1550,37.0
59.2050,34.0
59.2550,34.0
59.3050,44.0
59.3550,41.0
59.4050,39.0
59.4550,33.0
59.5050,36.0
59.5550,35.0
59.6050,36.0
59.6550,27.0
59.7050,35.0
59.7550,44.0
59.8050,36.0
59.8550,39.0
59.9050,35.0
59.9550,34.0
60.0050,40.0
60.0550,49.0
60.1050,35.0
60.1550,34.0
60.2050,42.0
60.2550,40.0
60.3050,42.0
60.3550,28.0
60.4050,35.0
60.4550,31.0
60.5050,37.0
60.5550,46.0
60.6050,42.0
60.6550,44.0
60.7050,43.0
60.7550,44.0
60.8050,34.0
60.8550,27.0
60.9050,41.0
60.9550,36.0
61.0050,40.0
61.0550,47.0
61.1050,29.0
61.1550,29.0
61.2050,26.0
61.2550,25.0
61.3050,43.0
61.3550,27.0
61.4050,37.0
61.4550,36.0
61.5050,34.0
61.5550,41.0
61.6050,36.0
61.6550,49.0
61.7050,30.0
61.7550,36.0
61.8050,42.0
61.8550,40.0
61.9050,34.0
61.9550,38.0
62.0050,28.0
62.0550,34.0
62.1050,32.0
62.1550,32.0
62.2050,38.0
62.2550,33.0
62.3050,44.0
62.3550,51.0
62.4050,45.0
62.4550,34.0
62.5050,42.0
62.5550,27.0
62.6050,38.0
62.6550,33.0
62.7050,40.0
62.7550,27.0
62.8050,37.0
62.8550,58.0
62.9050,59.0
62.9550,54.0
63.0050,99.0
63.0550,142.0
63.1050,313.0
63.1550,266.0
63.2050,153.0
63.2550,55.0
63.3050,46.0
63.3550,41.0
63.4050,40.0
63.4550,32.0
63.5050,33.0
63.5550,38.0
63.6050,35.0
63.6550,33.0
63.7050,27.0
63.7550,31.0
63.8050,31.0
63.8550,33.0
63.9050,35.0
63.9550,34.0
64.0050,26.0
64.0550,43.0
64.1050,32.0
64.1550,34.0
64.2050,26.0
64.2550,31.0
64.3050,43.0
64.3550,36.0
64.4050,41.0
64.4550,30.0
64.5050,28.0
64.5550,25.0
64.6050,42.0
64.6550,33.0
64.7050,39.0
64.7550,23.0
64.8050,30.0
64.8550,29.0
64.9050,30.0
64.9550,31.0
65.0050,36.0
65.0550,27.0
65.1050,36.0
65.1550,31.0
65.2050,37.0
65.2550,33.0
65.3050,25.0
65.3550,33.0
65.4050,34.0
65.4550,31.0
65.5050,43.0
65.5550,32.0
65.6050,21.0
65.6550,44.0
65.7050,45.0
65.7550,30.0
65.8050,33.0
65.8550,35.0
65.9050,31.0
65.9550,36.0
66.0050,32.0
66.0550,44.0
66.1050,37.0
66.1550,27.0
66.2050,30.0
66.2550,33.0
66.3050,34.0
66.3550,37.0
66.4050,34.0
66.4550,40.0
66.5050,29.0
66.5550,34.0
66.6050,40.0
66.6550,25.0
66.7050,36.0
66.7550,37.0
66.8050,37.0
66.8550,38.0
66.9050,30.0
66.9550,48.0
67.0050,33.0
67.0550,38.0
67.1050,44.0
67.1550,45.0
67.2050,48.0
67.2550,88.0
67.3050,152.0
67.3550,282.0
67.4050,528.0
67.4550,758.0
67.5050,720.0
67.5550,251.0
67.6050,100.0
67.6550,54.0
67.7050,37.0
67.7550,36.0
67.8050,37.0
67.8550,37.0
67.9050,35.0
67.9550,44.0
68.0050,30.0
68.0550,33.0
68.1050,41.0
68.1550,23.0
68.2050,37.0
68.2550,21.0
68.3050,34.0
68.3550,25.0
68.4050,28.0
68.4550,30.0
68.5050,31.0
68.5550,38.0
68.6050,29.0
68.6550,31.0
68.7050,43.0
68.7550,28.0
68.8050,34.0
68.8550,26.0
68.9050,38.0
68.9550,36.0
69.0050,40.0
69.0550,33.0
69.1050,36.0
69.1550,34.0
69.2050,32.0
69.2550,26.0
69.3050,35.0
69.3550,30.0
69.4050,31.0
69.4550,24.0
69.5050,31.0
69.5550,36.0
69.6050,33.0
69.6550,30.0
69.7050,21.0
69.7550,24.0
69.8050,37.0
69.8550,30.0
69.9050,19.0
69.9550,36.0
70.0050,32.0
70.0550,42.0
70.1050,30.0
70.1550,21.0
70.2050,27.0
70.2550,35.0
70.3050,21.0
70.3550,35.0
70.4050,33.0
70.4550,26.0
70.5050,26.0
70.5550,23.0
70.6050,35.0
70.6550,32.0
70.7050,30.0
70.7550,33.0
70.8050,28.0
70.8550,22.0
70.9050,37.0
70.9550,32.0
71.0050,27.0
71.0550,32.0
71.1050,29.0
71.1550,34.0
71.2050,34.0
71.2550,28.0
71.3050,36.0
71.3550,39.0
71.4050,59.0
71.4550,64.0
71.5050,92.0
71.5550,177.0
71.6050,338.0
71.6550,671.0
71.7050,486.0
71.7550,170.0
71.8050,62.0
71.8550,44.0
71.9050,44.0
71.9550,36.0
72.0050,34.0
72.0550,37.0
72.1050,36.0
72.1550,30.0
72.2050,24.0
72.2550,23.0
72.3050,26.0
72.3550,28.0
72.4050,31.0
72.4550,36.0
72.5050,36.0
72.5550,34.0
72.6050,42.0
72.6550,30.0
72.7050,28.0
72.7550,31.0
72.8050,33.0
72.8550,33.0
72.9050,32.0
72.9550,33.0
73.0050,26.0
73.0550,29.0
73.1050,31.0
73.1550,22.0
73.2050,33.0
73.2550,26.0
73.3050,31.0
73.3550,39.0
73.4050,29.0
73.4550,31.0
73.5050,31.0
73.5550,23.0
73.6050,26.0
73.6550,29.0
73.7050,31.0
73.7550,42.0
73.8050,31.0
73.8550,29.0
73.9050,32.0
73.9550,35.0
74.0050,35.0
74.0550,22.0
74.1050,27.0
74.1550,18.0
74.2050,33.0
74.2550,35.0
74.3050,36.0
74.3550,15.0
74.4050,27.0
74.4550,28.0
74.5050,32.0
74.5550,19.0
74.6050,30.0
74.6550,28.0
74.7050,41.0
74.7550,37.0
74.8050,21.0
74.8550,32.0
74.9050,34.0
74.9550,27.0
75.0050,30.0
75.0550,34.0
75.1050,31.0
75.1550,30.0
75.2050,32.0
75.2550,24.0
75.3050,33.0
75.3550,22.0
75.4050,34.0
75.4550,45.0
75.5050,40.0
75.5550,61.0
75.6050,67.0
75.6550,154.0
75.7050,198.0
75.7550,365.0
75.8050,245.0
75.8550,125.0
75.9050,49.0
75.9550,40.0
76.0050,32.0
76.0550,28.0
76.1050,34.0
76.1550,28.0
76.2050,33.0
76.2550,37.0
76.3050,26.0
76.3550,26.0
76.4050,29.0
76.4550,27.0
76.5050,33.0
76.5550,29.0
76.6050,36.0
76.6550,30.0
76.7050,29.0
76.7550,23.0
76.8050,28.0
76.8550,36.0
76.9050,25.0
76.9550,30.0
77.0050,34.0
77.0550,30.0
77.1050,38.0
77.1550,28.0
77.2050,33.0
77.2550,21.0
77.3050,27.0
77.3550,27.0
77.4050,21.0
77.4550,28.0
77.5050,26.0
77.5550,31.0
77.6050,22.0
77.6550,28.0
77.7050,23.0
77.7550,30.0
77.8050,28.0
77.8550,23.0
77.9050,28.0
77.9550,26.0
78.0050,26.0
78.0550,26.0
78.1050,30.0
78.1550,32.0
78.2050,26.0
78.2550,23.0
78.3050,35.0
78.3550,21.0
78.4050,34.0
78.4550,26.0
78.5050,37.0
78.5550,34.0
78.6050,32.0
78.6550,26.0
78.7050,36.0
78.7550,29.0
78.8050,24.0
78.8550,33.0
78.9050,22.0
78.9550,20.0
79.0050,28.0
79.0550,35.0
79.1050,25.0
79.1550,35.0
79.2050,29.0
79.2550,27.0
79.3050,23.0
79.3550,31.0
79.4050,31.0
79.4550,32.0
79.5050,31.0
79.5550,26.0
79.6050,25.0
79.6550,33.0
79.7050,46.0
79.7550,66.0
79.8050,93.0
79.8550,52.0
79.9050,33.0
79.9550,34.0
80.0050,20.0
80.0550,27.0
80.1050,28.0
80.1550,29.0
80.2050,26.0
80.2550,21.0
80.3050,32.0
80.3550,31.0
80.4050,22.0
80.4550,33.0
80.5050,22.0
80.5550,18.0
80.6050,18.0
80.6550,32.0
80.7050,26.0
80.7550,36.0
80.8050,20.0
80.8550,24.0
80.9050,30.0
80.9550,19.0
81.0050,19.0
81.0550,22.0
81.1050,21.0
81.1550,21.0
81.2050,20.0
81.2550,19.0
81.3050,33.0
81.3550,27.0
81.4050,27.0
81.4550,32.0
81.5050,27.0
81.5550,24.0
81.6050,24.0
81.6550,35.0
81.7050,17.0
81.7550,30.0
81.8050,30.0
81.8550,26.0
81.9050,26.0
81.9550,35.0
82.0050,27.0
82.0550,30.0
82.1050,24.0
82.1550,30.0
82.2050,32.0
82.2550,21.0
82.3050,33.0
82.3550,27.0
82.4050,24.0
82.4550,22.0
82.5050,21.0
82.5550,29.0
82.6050,26.0
82.6550,33.0
82.7050,19.0
82.7550,35.0
82.8050,23.0
82.8550,30.0
82.9050,29.0
82.9550,28.0
83.0050,26.0
83.0550,24.0
83.1050,32.0
83.1550,25.0
83.2050,29.0
83.2550,33.0
83.3050,18.0
83.3550,36.0
83.4050,28.0
83.4550,28.0
83.5050,33.0
83.5550,43.0
83.6050,52.0
83.6550,84.0
83.7050,162.0
83.7550,207.0
83.8050,172.0
83.8550,96.0
83.9050,45.0
83.9550,33.0
84.0050,33.0
84.0550,32.0
84.1050,20.0
84.1550,34.0
84.2050,22.0
84.2550,34.0
84.3050,29.0
84.3550,28.0
84.4050,25.0
84.4550,30.0
84.5050,31.0
84.5550,25.0
84.6050,27.0
84.6550,35.0
84.7050,34.0
84.7550,24.0
84.8050,25.0
84.8550,25.0
84.9050,20.0
84.9550,27.0
85.0050,19.0
85.0550,29.0
85.1050,26.0
85.1550,29.0
85.2050,23.0
85.2550,21.0
85.3050,24.0
85.3550,19.0
85.4050,32.0
85.4550,25.0
85.5050,28.0
85.5550,31.0
85.6050,26.0
85.6550,29.0
85.7050,30.0
85.7550,22.0
85.8050,29.0
85.8550,34.0
85.9050,23.0
85.9550,35.0
86.0050,31.0
86.0550,25.0
86.1050,25.0
86.1550,39.0
86.2050,29.0
86.2550,27.0
86.3050,28.0
86.3550,20.0
86.4050,22.0
86.4550,30.0
86.5050,28.0
86.5550,26.0
86.6050,27.0
86.6550,21.0
86.7050,23.0
86.7550,38.0
86.8050,34.0
86.8550,36.0
86.9050,32.0
86.9550,24.0
87.0050,34.0
87.0550,21.0
87.1050,35.0
87.1550,19.0
87.2050,37.0
87.2550,30.0
87.3050,29.0
87.3550,33.0
87.4050,44.0
87.4550,32.0
87.5050,52.0
87.5550,81.0
87.6050,166.0
87.6550,296.0
87.7050,424.0
87.7550,362.0
87.8050,161.0
87.8550,70.0
87.9050,44.0
87.9550,35.0
88.0050,40.0
88.0550,35.0
88.1050,26.0
88.1550,22.0
88.2050,35.0
88.2550,34.0
88.3050,28.0
88.3550,36.0
88.4050,32.0
88.4550,33.0
88.5050,39.0
88.5550,26.0
88.6050,22.0
88.6550,32.0
88.7050,32.0
88.7550,27.0
88.8050,40.0
88.8550,29.0
88.9050,36.0
88.9550,20.0
89.0050,24.0
89.0550,35.0
89.1050,32.0
89.1550,29.0
89.2050,29.0
89.2550,31.0
89.3050,30.0
89.3550,30.0
89.4050,25.0
89.4550,26.0
89.5050,27.0
89.5550,36.0
89.6050,37.0
89.6550,21.0
89.7050,28.0
89.7550,25.0
89.8050,18.0
89.8550,18.0
89.9050,13.0
89.9550,34.0
89.9950,27.0